Workbook

Sheet Data_Dictionary
A1: Column Name | B1: Description | C1: Formula | D1: Why It Matters
A2: ROE | B2: Return on Equity | C2: PAT ÷ Equity | D2: Measures profitability for shareholders
A3: ROA | B3: Return on Assets | C3: PAT ÷ Assets | D3: Measures efficiency
A4: Debt-to-Equity | B4: Liabilities ÷ Equity | C4: Liabilities ÷ Equity | D4: Measures leverage
A5: Asset Growth | B5: Year-on-Year Asset Change | C5: ((Current−Previous)/Previous)×100 | D5: Shows expansion
A6: Profit Growth | B6: Year-on-Year Profit Change | C6: ((Current−Previous)/Previous)×100 | D6: Shows earnings trend
A7: years profitable | D7: Counts how many years the company made a profit.
A8: dividend years | D8: Counts the number of years dividends were actually paid.

Sheet RAW_DATA
A1: COMPANY | B1: TICKER | C1: SECTOR | D1: YEAR | E1: TOTAL ASSETS | F1: TOTAL LIABILITES | G1: TOTAL EQUITY | H1: PROFIT BEFORE TAX | I1: PROFIT AFTER TAX | J1: NET INTEREST INCOME | K1: FEES & COMMISION INCOME | L1: BASIC EPS(EARNINGS PER SHARE) | M1: DPS(DIVIDEND PER SHARE) | N1: RETAINED EARNINGS | O1: SOURCE
A2: Guaranty Trust Holding Company | B2: GTCO | C2: Banking | D2: 2020 | E2: =SUM(F2,G2) -> 4944653293000 | F2: 4130257616000 | G2: 814395677000 | H2: 238095070000 | I2: 201439940000 | J2: 253668147000 | K2: 53179802000 | L2: 7.11 | M2: 3 | N2: 193921810000 | O2: GTCO Annual Report 2021
A3: Guaranty Trust Holding Company | B3: GTCO | C3: Banking | D3: 2021 | E3: =SUM(F3,G3) -> 5436034997000 | F3: 4552807905000 | G3: 883227092000 | H3: 221497676000 | I3: 174839487000 | J3: 220612622000 | K3: 74123774000 | L3: 6.14 | M3: 3 | N3: 198358025000 | O3: GTCO Annual Report 2021
A4: Guaranty Trust Holding Company | B4: GTCO | C4: Banking | D4: 2022 | E4: =SUM(F4,G4) -> 6446456429000 | F4: 5515307227000 | G4: 931149202000 | H4: 214154094000 | I4: 169173437000 | J4: 259303127000 | K4: 90612848000 | L4: 5.95 | M4: 3 | N4: 214858054000 | O4: GTCO Annual Report 2022
A5: Guaranty Trust Holding Company | B5: GTCO | C5: Banking | D5: 2023 | E5: =SUM(F5,G5) -> 9691254678000 | F5: 8214126607000 | G5: 1477128071000 | H5: 609308442000 | I5: 539654674000 | J5: 436696585000 | K5: 124162260000 | L5: 19.07 | M5: 3.3 | N5: 580033938000 | O5: GTCO Annual Report 2023
A6: Guaranty Trust Holding Company | B6: GTCO | C6: Banking | D6: 2024 | E6: =SUM(F6,G6) -> 14795706831000 | F6: 12083689217000 | G6: 2712017614000 | H6: 1266246073000 | I6: 1017802849000 | J6: 1058586173000 | K6: 221231208000 | L6: 35.44 | M6: 3.7 | N6: 1319841616000 | O6: GTCO Annual Report 2024
A7: Guaranty Trust Holding Company | B7: GTCO | C7: Banking | D7: 2025 | E7: =SUM(F7,G7) -> 17761152255000 | F7: 14349772297000 | G7: 3411379958000 | H7: 1231081326000 | I7: 865746687000 | J7: 1260586840000 | K7: 278505492000 | L7: 25.43 | M7: 8.03 | N7: 1718423706000 | O7: GTCO Annual Report 2025
A8: Zenith Bank | B8: ZENITH BANK | C8: Banking | D8: 2020 | E8: =SUM(F8,G8) -> 8481273000000 | F8: 7363800000000 | G8: 1117473000000 | H8: 255861000000 | I8: 230565000000 | J8: 299682000000 | K8: 79332000000 | L8: 7.34 | M8: 2.7 | N8: 521293000000 | O8: ZENITH Annual Report 2021
A9: Zenith Bank | B9: ZENITH BANK | C9: Banking | D9: 2021 | E9: =SUM(F9,G9) -> 9447843000000 | F9: 8168181000000 | G9: 1279662000000 | H9: 280374000000 | I9: 244558000000 | J9: 320804000000 | K9: 103958000000 | L9: 7.78 | M9: 2.8 | N9: 607203000000 | O9: ZENITH Annual Report 2021
A10: Zenith Bank | B10: ZENITH BANK | C10: Banking | D10: 2022 | E10: =SUM(F10,G10) -> 12285629000000 | F10: 10906689000000 | G10: 1378940000000 | H10: 284650000000 | I10: 223911000000 | J10: 366627000000 | K10: 132795000000 | L10: 7.14 | M10: 2.9 | N10: 625005000000 | O10: ZENITH Annual Report 2022
A11: Zenith Bank | B11: ZENITH BANK | C11: Banking | D11: 2023 | E11: =SUM(F11,G11) -> 20368455000000 | F11: 18045075000000 | G11: 2323380000000 | H11: 795962000000 | I11: 676909000000 | J11: 736182000000 | K11: 109307000000 | L11: 21.55 | M11: 3.5 | N11: 1179390000000 | O11: ZENITH Annual Report 2023
A12: Zenith Bank | B12: ZENITH BANK | C12: Banking | D12: 2024 | E12: =SUM(F12,G12) -> 29957525000000 | F12: 25928252000000 | G12: 4029273000000 | H12: 1326851000000 | I12: 1032895000000 | J12: 1728903000000 | K12: 206867000000 | L12: 32.87 | M12: 4 | N12: 2015513000000 | O12: ZENITH Annual Report 2024
A13: Zenith Bank | B13: ZENITH BANK | C13: Banking | D13: 2025 | E13: =SUM(F13,G13) -> 31458051000000 | F13: 26533845000000 | G13: 4924206000000 | H13: 1263370000000 | I13: 1040546000000 | J13: 2639532000000 | K13: 291800000000 | L13: 25.32 | M13: 8.75 | N13: 2808194000000 | O13: ZENITH Annual Report 2025
A14: MTN Nigeria Communications Network | B14: MTN | C14: Telecomunication | D14: 2020 | E14: =SUM(F14,G14) -> 1963543000000 | F14: 1785157000000 | G14: 178386000000 | H14: 298874000000 | I14: 205214000000 | J14: N/A | K14: N/A | L14: 10.8 | M14: 9.4 | N14: 160524000000 | O14: MTN Annual Report 2021
A15: MTN Nigeria Communications Network | B15: MTN | C15: Telecomunication | D15: 2021 | E15: =SUM(F15,G15) -> 2259555000000 | F15: 1994574000000 | G15: 264981000000 | H15: 436687000000 | I15: 298654000000 | J15: N/A | K15: N/A | L15: 14.67 | M15: 13.1 | N15: 246473000000 | O15: MTN Annual Report 2021
A16: MTN Nigeria Communications Network | B16: MTN | C16: Telecomunication | D16: 2022 | E16: =SUM(F16,G16) -> 2539369000000 | F16: 2276827000000 | G16: 262542000000 | H16: 518823000000 | I16: 348727000000 | J16: N/A | K16: N/A | L16: 16.63 | M16: 15.6 | N16: 246679000000 | O16: MTN Annual Report 2022
A17: MTN Nigeria Communications Network | B17: MTN | C17: Telecomunication | D17: 2023 | E17: =SUM(F17,G17) -> 3188827000000 | F17: 3229671000000 | G17: -40844000000 | H17: -177885000000 | I17: -137020000000 | J17: N/A | K17: N/A | L17: -6.53 | M17: 5.6 | N17: -208018000000 | O17: MTN Annual Report 2023
A18: MTN Nigeria Communications Network | B18: MTN | C18: Telecomunication | D18: 2024 | E18: =SUM(F18,G18) -> 4196991000000 | F18: 4654998000000 | G18: -458007000000 | H18: -550325000000 | I18: -400435000000 | J18: N/A | K18: N/A | L18: -19.05 | M18: 0 | N18: -607466000000 | O18: MTN Annual Report 2024
A19: MTN Nigeria Communications Network | B19: MTN | C19: Telecomunication | D19: 2025 | E19: =SUM(F19,G19) -> 5403489000000 | F19: 4854777000000 | G19: 548712000000 | H19: 1696029000000 | I19: 1112846000000 | J19: N/A | K19: N/A | L19: 53.07 | M19: 20 | N19: 404402000000 | O19: MTN Annual Report 2025
A20: Presco | B20: PRESCO | C20: Agriculture | D20: 2020 | E20: N/A | F20: N/A | G20: N/A | H20: N/A | I20: N/A | J20: N/A | K20: N/A | L20: N/A | M20: N/A | N20: N/A | O20: PRESCO Annual Report 2021
A21: Presco | B21: PRESCO | C21: Agriculture | D21: 2021 | E21: =SUM(F21,G21) -> 140606312000 | F21: 110825029000 | G21: 29781283000 | H21: 26378270000 | I21: 19319953000 | J21: N/A | K21: N/A | L21: 19.32 | M21: 0 | N21: 45843042000 | O21: PRESCO Annual Report 2021
A22: Presco | B22: PRESCO | C22: Agriculture | D22: 2022 | E22: =SUM(F22,G22) -> 132369448000 | F22: 98208883000 | G22: 34160565000 | H22: 19814841000 | I22: 13032424000 | J22: N/A | K22: N/A | L22: 13.03 | M22: not included | N22: 32430726000 | O22: PRESCO Annual Report 2022
A23: Presco | B23: PRESCO | C23: Agriculture | D23: 2023 | E23: =SUM(F23,G23) -> 170278145000 | F23: 113115092000 | G23: 57163053000 | H23: 50006525000 | I23: 32861334000 | J23: N/A | K23: N/A | L23: 32.86 | M23: not included | N23: 56501292000 | O23: PRESCO Annual Report 2023
A24: Presco | B24: PRESCO | C24: Agriculture | D24: 2024 | E24: =SUM(F24,G24) -> 475096189000 | F24: 263911588000 | G24: 211184601000 | H24: 113223279000 | I24: 77793086000 | J24: N/A | K24: N/A | L24: 120.64 | M24: 42 | N24: 126729311000 | O24: PRESCO Annual Report 2024
A25: Presco | B25: PRESCO | C25: Agriculture | D25: 2025 | E25: =SUM(F25,G25) -> 926008472000 | F25: 483259026000 | G25: 442749446000 | H25: 177979216000 | I25: 121354087000 | J25: N/A | K25: N/A | L25: 76.07 | M25: 44.66 | N25: 176083398000 | O25: PRESCO Annual Report 2025
A26: Dangote Cement | B26: DANGCEM | C26: Industrial Goods | D26: 2020 | E26: =SUM(F26,G26) -> 2022451000000 | F26: 1131481000000 | G26: 890970000000 | H26: 373310000000 | I26: 276068000000 | J26: N/A | K26: N/A | L26: 16.14 | M26: 16 | N26: 779271000000 | O26: Dangote Cement Plc 2021 annual report
A27: Dangote Cement | B27: DANGCEM | C27: Industrial Goods | D27: 2021 | E27: =SUM(F27,G27) -> 2392019000000 | F27: 1408350000000 | G27: 983669000000 | H27: 538366000000 | I27: 364439000000 | J27: N/A | K27: N/A | L27: 21.24 | M27: 20 | N27: 868274000000 | O27: Dangote Cement Plc 2021 annual report
A28: Dangote Cement | B28: DANGCEM | C28: Industrial Goods | D28: 2022 | E28: =SUM(F28,G28) -> 2615655000000 | F28: 1536708000000 | G28: 1078947000000 | H28: 524002000000 | I28: 382311000000 | J28: N/A | K28: N/A | L28: 22.27 | M28: 20 | N28: 969478000000 | O28: Dangote Cement Plc 2022 annual report
A29: Dangote Cement | B29: DANGCEM | C29: Industrial Goods | D29: 2023 | E29: =SUM(F29,G29) -> 3938725000000 | F29: 2212885000000 | G29: 1725840000000 | H29: 553104000000 | I29: 455583000000 | J29: N/A | K29: N/A | L29: 26.47 | M29: 30 | N29: 1098626000000 | O29: Dangote Cement Plc 2023 annual report
A30: Dangote Cement | B30: DANGCEM | C30: Industrial Goods | D30: 2024 | E30: =SUM(F30,G30) -> 6403238000000 | F30: 4227993000000 | G30: 2175245000000 | H30: 732537000000 | I30: 503247000000 | J30: N/A | K30: N/A | L30: 29.74 | M30: 30 | N30: 1027046000000 | O30: Dangote Cement Plc 2024 annual report
A31: Dangote Cement | B31: DANGCEM | C31: Industrial Goods | D31: 2025 | E31: =SUM(F31,G31) -> 6040727000000 | F31: 3420591000000 | G31: 2620136000000 | H31: 1532660000000 | I31: 1014921000000 | J31: N/A | K31: N/A | L31: 59.86 | M31: 45 | N31: 1505365000000 | O31: Dangote Cement Plc 2025 annual report
A32: Seplat Energy | B32: SEPLAT | C32: Oil & Gas | D32: 2020 | E32: =SUM(F32,G32) -> 1310837000000 | F32: 678500000000 | G32: 632337000000 | H32: -28872000000 | I32: -30712000000 | J32: N/A | K32: N/A | L32: -46.42 | M32: 37.95 | N32: 211790000000 | O32: SEPLAT Annual Report 2021
A33: Seplat Energy | B33: SEPLAT | C33: Oil & Gas | D33: 2021 | E33: =SUM(F33,G33) -> 1603536000000 | F33: 900172000000 | G33: 703364000000 | H33: 71028000000 | I33: 46931000000 | J33: N/A | K33: N/A | L33: 97.63 | M33: 41.03 | N33: 239429000000 | O33: SEPLAT Annual Report 2021
A34: Seplat Energy | B34: SEPLAT | C34: Oil & Gas | D34: 2022 | E34: =SUM(F34,G34) -> 1489980000000 | F34: 703086000000 | G34: 786894000000 | H34: 86730000000 | I34: 44433000000 | J34: N/A | K34: N/A | L34: 45 | M34: 46.15 | N34: 241386000000 | O34: SEPLAT Annual Report 2022
A35: Seplat Energy | B35: SEPLAT | C35: Oil & Gas | D35: 2023 | E35: =SUM(F35,G35) -> 3053454000000 | F35: 1440819000000 | G35: 1612635000000 | H35: 125540000000 | I35: 81330000000 | J35: N/A | K35: N/A | L35: 92.75 | M35: 108.85 | N35: 230708000000 | O35: SEPLAT Annual Report 2023
... A37: Seplat Energy | B37: SEPLAT | C37: Oil & Gas | D37: 2025 | E37: =SUM(F37,G37) -> 8729381000000 | F37: 6086145000000 | G37: 2643236000000 | H37: 755505000000 | I37: 241580000000 | J37: N/A | K37: N/A | L37: 409.92 | M37: 379.39 | N37: 342409000000 | O37: SEPLAT Annual Report 2025
B40: LIMITATIONS
A41: N.B | B41: All financial statement figures are reported in Nigerian Naira as presented in the respective annual reports unless otherwise stated. EPS is reported in the unit disclosed by each company's annual report.
A42: N.B | B42: Seplat Energy declares dividends in US dollars. Dividend per share figures were converted to Nigerian Naira using the CBN official year-end exchange rate for each respective year to maintain consistency across companies."
A43: N.B | B43: Presco's 2021 Annual Report is the first to present consolidated Group financial statements following the acquisition of Siat Nigeria Limited. Consequently, no Group comparative figures are available for 2020, and only the Parent Company financial statements are presented for that year
...

Sheet COMPANY SUMMARY
A1: COMPANY | B1: SECTOR | C1: AVG ROE(%) | D1: AVG ROA(%) | E1: AVG Debt/Equity | F1: AVG Equity Ratio(%) | G1: AVG Asset Growth(%) | H1: AVG Profit Growth(%) | I1: AVG EPS(#) | J1: AVG DPS(#) | K1: TOTAL PAT(#) | L1: AVG PAT(#) | M1: Total Assets(#) | N1: AVG Total Assets(#) | O1: Years Profitable | P1: Dividend Years | Q1: Highest EPS | R1: Highest DPS | S1: Highest ROE | T1: Highest Profit Growth | U1: Highest Assets Growth | V1: Profitability Score | W1: Growth Score | X1: Financial Health Score | Y1: OVERALL INVESTMENT SCORE
A2: GTCO | B2: =VLOOKUP(A2, RAW_DATA!B:C, 2, FALSE) -> Banking | C2: =AVERAGEIF(RATIOS!A:A,A2,RATIOS!C:C) -> 0.27023379 | D2: =AVERAGEIF(RATIOS!A:A,A2,RATIOS!D:D) -> 0.045393969 | E2: =AVERAGEIF(RATIOS!A:A,A2,RATIOS!E:E) -> 5.0620582 | F2: =AVERAGEIF(RATIOS!A:A,A2,RATIOS!F:F) -> 0.16656803 | G2: =AVERAGEIF(RATIOS!A:A,A2,RATIOS!G:G) -> 0.30314605 | H2: =AVERAGEIF(RATIOS!A:A,A2,RATIOS!H:H) -> 0.55242405 | I2: =AVERAGEIF(RAW_DATA!B:B,A2,RAW_DATA!L:L) -> 16.523333 | J2: =AVERAGEIF(RAW_DATA!B:B,A2,RAW_DATA!M:M) -> 4.005 | K2: =SUMIF(RAW_DATA!B:B,A2,RAW_DATA!I:I) -> 2968657074000 | L2: =AVERAGEIF(RAW_DATA!B:B,A2,RAW_DATA!H:H) -> 630063780167 | M2: =SUMIF(RAW_DATA!B:B,A2,RAW_DATA!E:E) -> 59075258483000 | N2: =AVERAGEIF(RAW_DATA!B:B,A2,RAW_DATA!E:E) -> 9845876413833 | O2: =COUNTIFS(RAW_DATA!B:B,A2,RAW_DATA!H:H,">0") -> 6 | P2: =COUNTIFS(RAW_DATA!B:B,A2,RAW_DATA!M:M,">0") -> 6 | Q2: =MAXIFS(RAW_DATA!L:L,RAW_DATA!B:B,A2) -> 35.44 | R2: =MAXIFS(RAW_DATA!M:M,RAW_DATA!B:B,A2) -> 8.03 | S2: =MAXIFS(RATIOS!C:C,RATIOS!A:A,A2) -> 0.3752936 | T2: =MAXIFS(RATIOS!H:H,RATIOS!A:A,A2) -> 2.1899492 | U2: =MAXIFS(RATIOS!G:G,RATIOS!A:A,A2) -> 0.52670705 | V2: 9.651591 | W2: 48.669743 | X2: 22.176352 | Y2: 25.114465
A3: Zenith Bank | B3: =VLOOKUP(A3, RAW_DATA!B:C, 2, FALSE) -> Banking | C3: =AVERAGEIF(RATIOS!A:A,A3,RATIOS!C:C) -> 0.21980407 | D3: =AVERAGEIF(RATIOS!A:A,A3,RATIOS!D:D) -> 0.0286808 | E3: =AVERAGEIF(RATIOS!A:A,A3,RATIOS!E:E) -> 6.7453993 | F3: =AVERAGEIF(RATIOS!A:A,A3,RATIOS!F:F) -> 0.13075703 | G3: =AVERAGEIF(RATIOS!A:A,A3,RATIOS!G:G) -> 0.31862129 | H3: =AVERAGEIF(RATIOS!A:A,A3,RATIOS!H:H) -> 0.50653745 | I3: =AVERAGEIF(RAW_DATA!B:B,A3,RAW_DATA!L:L) -> 17 | J3: =AVERAGEIF(RAW_DATA!B:B,A3,RAW_DATA!M:M) -> 4.1083333 | K3: =SUMIF(RAW_DATA!B:B,A3,RAW_DATA!I:I) -> 3449384000000 | L3: =AVERAGEIF(RAW_DATA!B:B,A3,RAW_DATA!H:H) -> 701178000000 | M3: =SUMIF(RAW_DATA!B:B,A3,RAW_DATA!E:E) -> 111998776000000 | N3: =AVERAGEIF(RAW_DATA!B:B,A3,RAW_DATA!E:E) -> 18666462666667 | O3: =COUNTIFS(RAW_DATA!B:B,A3,RAW_DATA!H:H,">0") -> 6 | P3: =COUNTIFS(RAW_DATA!B:B,A3,RAW_DATA!M:M,">0") -> 6 | Q3: =MAXIFS(RAW_DATA!L:L,RAW_DATA!B:B,A3) -> 32.87 | R3: =MAXIFS(RAW_DATA!M:M,RAW_DATA!B:B,A3) -> 8.75 | S3: =MAXIFS(RATIOS!C:C,RATIOS!A:A,A3) -> 0.29134666 | T3: =MAXIFS(RATIOS!H:H,RATIOS!A:A,A3) -> 2.0231163 | U3: =MAXIFS(RATIOS!G:G,RATIOS!A:A,A3) -> 0.65790901 | V3: 5.6515914 | W3: 48.415743 | X3: 11.203408 | Y3: 20.146382
A4: MTN | B4: =VLOOKUP(A4, RAW_DATA!B:C, 2, FALSE) -> Telecomunication | C4: =AVERAGEIF(RATIOS!A:A,A4,RATIOS!C:C) -> 1.6438102 | D4: =AVERAGEIF(RATIOS!A:A,A4,RATIOS!D:D) -> 0.073597475 | E4: =AVERAGEIF(RATIOS!A:A,A4,RATIOS!E:E) -> -9.0304322 | F4: =AVERAGEIF(RATIOS!A:A,A4,RATIOS!F:F) -> 0.048520137 | G4: =AVERAGEIF(RATIOS!A:A,A4,RATIOS!G:G) -> 0.22679361 | H4: =AVERAGEIF(RATIOS!A:A,A4,RATIOS!H:H) -> -0.52531183 | I4: =AVERAGEIF(RAW_DATA!B:B,A4,RAW_DATA!L:L) -> 11.598333 | J4: =AVERAGEIF(RAW_DATA!B:B,A4,RAW_DATA!M:M) -> 10.616667 | K4: =SUMIF(RAW_DATA!B:B,A4,RAW_DATA!I:I) -> 1427986000000 | L4: =AVERAGEIF(RAW_DATA!B:B,A4,RAW_DATA!H:H) -> 370367166667 | M4: =SUMIF(RAW_DATA!B:B,A4,RAW_DATA!E:E) -> 19551774000000 | N4: =AVERAGEIF(RAW_DATA!B:B,A4,RAW_DATA!E:E) -> 3258629000000 | O4: =COUNTIFS(RAW_DATA!B:B,A4,RAW_DATA!H:H,">0") -> 4 | P4: =COUNTIFS(RAW_DATA!B:B,A4,RAW_DATA!M:M,">0") -> 5 | Q4: =MAXIFS(RAW_DATA!L:L,RAW_DATA!B:B,A4) -> 53.07 | R4: =MAXIFS(RAW_DATA!M:M,RAW_DATA!B:B,A4) -> 20 | S4: =MAXIFS(RATIOS!C:C,RATIOS!A:A,A4) -> 3.3547155 | T4: =MAXIFS(RATIOS!H:H,RATIOS!A:A,A4) -> 1.9224566 | U4: =MAXIFS(RATIOS!G:G,RATIOS!A:A,A4) -> 0.31615513 | V4: 36.958402 | W4: 0 | X4: 43.121567 | Y4: 27.719831
A5: DANGCEM | B5: =VLOOKUP(A5, RAW_DATA!B:C, 2, FALSE) -> Industrial Goods | C5: =AVERAGEIF(RATIOS!A:A,A5,RATIOS!C:C) -> 0.31956023 | D5: =AVERAGEIF(RATIOS!A:A,A5,RATIOS!D:D) -> 0.1328823 | E5: =AVERAGEIF(RATIOS!A:A,A5,RATIOS!E:E) -> 1.4428893 | F5: =AVERAGEIF(RATIOS!A:A,A5,RATIOS!F:F) -> 0.4126488 | G5: =AVERAGEIF(RATIOS!A:A,A5,RATIOS!G:G) -> 0.27023048 | H5: =AVERAGEIF(RATIOS!A:A,A5,RATIOS!H:H) -> 0.33643368 | I5: =AVERAGEIF(RAW_DATA!B:B,A5,RAW_DATA!L:L) -> 29.286667 | J5: =AVERAGEIF(RAW_DATA!B:B,A5,RAW_DATA!M:M) -> 26.833333 | K5: =SUMIF(RAW_DATA!B:B,A5,RAW_DATA!I:I) -> 2996569000000 | L5: =AVERAGEIF(RAW_DATA!B:B,A5,RAW_DATA!H:H) -> 708996500000 | M5: =SUMIF(RAW_DATA!B:B,A5,RAW_DATA!E:E) -> 23412815000000 | N5: =AVERAGEIF(RAW_DATA!B:B,A5,RAW_DATA!E:E) -> 3902135833333 | O5: =COUNTIFS(RAW_DATA!B:B,A5,RAW_DATA!H:H,">0") -> 6 | P5: =COUNTIFS(RAW_DATA!B:B,A5,RAW_DATA!M:M,">0") -> 6 | Q5: =MAXIFS(RAW_DATA!L:L,RAW_DATA!B:B,A5) -> 59.86 | R5: =MAXIFS(RAW_DATA!M:M,RAW_DATA!B:B,A5) -> 45 | S5: =MAXIFS(RATIOS!C:C,RATIOS!A:A,A5) -> 0.38735432 | T5: =MAXIFS(RATIOS!H:H,RATIOS!A:A,A5) -> 1.0167453 | U5: =MAXIFS(RATIOS!G:G,RATIOS!A:A,A5) -> 0.6257134 | V5: 33.377005 | W5: 37.205586 | X5: 75.972096 | Y5: 47.304107
A6: Seplat | B6: =VLOOKUP(A6, RAW_DATA!B:C, 2, FALSE) -> Oil & Gas | C6: =AVERAGEIF(RATIOS!A:A,A6,RATIOS!C:C) -> 0.048350022 | D6: =AVERAGEIF(RATIOS!A:A,A6,RATIOS!D:D) -> 0.018299734 | E6: =AVERAGEIF(RATIOS!A:A,A6,RATIOS!E:E) -> 1.5260818 | F6: =AVERAGEIF(RATIOS!A:A,A6,RATIOS!F:F) -> 0.42488646 | G6: =AVERAGEIF(RATIOS!A:A,A6,RATIOS!G:G) -> 0.69352583 | H6: =AVERAGEIF(RATIOS!A:A,A6,RATIOS!H:H) -> -0.0065770241 | I6: =AVERAGEIF(RAW_DATA!B:B,A6,RAW_DATA!L:L) -> 162.275 | J6: =AVERAGEIF(RAW_DATA!B:B,A6,RAW_DATA!M:M) -> 165.46 | K6: =SUMIF(RAW_DATA!B:B,A6,RAW_DATA!I:I) -> 591431000000 | L6: =AVERAGEIF(RAW_DATA!B:B,A6,RAW_DATA!H:H) -> 234100000000 | M6: =SUMIF(RAW_DATA!B:B,A6,RAW_DATA!E:E) -> 26669982000000 | N6: =AVERAGEIF(RAW_DATA!B:B,A6,RAW_DATA!E:E) -> 4444997000000 | O6: =COUNTIFS(RAW_DATA!B:B,A6,RAW_DATA!H:H,">0") -> 5 | P6: =COUNTIFS(RAW_DATA!B:B,A6,RAW_DATA!M:M,">0") -> 6 | Q6: =MAXIFS(RAW_DATA!L:L,RAW_DATA!B:B,A6) -> 409.92 | R6: =MAXIFS(RAW_DATA!M:M,RAW_DATA!B:B,A6) -> 379.39 | S6: =MAXIFS(RATIOS!C:C,RATIOS!A:A,A6) -> 0.091395547 | T6: =MAXIFS(RATIOS!H:H,RATIOS!A:A,A6) -> 1.5558711 | U6: =MAXIFS(RATIOS!G:G,RATIOS!A:A,A6) -> 2.4330938 | V6: 50 | W6: 65.174668 | X6: 49.925279 | Y6: 54.529984
A7: Presco | B7: =VLOOKUP(A7, RAW_DATA!B:C, 2, FALSE) -> Agriculture | C7: =AVERAGEIF(RATIOS!A:A,A7,RATIOS!C:C) -> 0.4495121 | D7: =AVERAGEIF(RATIOS!A:A,A7,RATIOS!D:D) -> 0.14472764 | E7: =AVERAGEIF(RATIOS!A:A,A7,RATIOS!E:E) -> 2.1832401 | F7: =AVERAGEIF(RATIOS!A:A,A7,RATIOS!F:F) -> 0.34564319 | G7: =AVERAGEIF(RATIOS!A:A,A7,RATIOS!G:G) -> 0.74175494 | H7: =AVERAGEIF(RATIOS!A:A,A7,RATIOS!H:H) -> 0.78083429 | I7: =AVERAGEIF(RAW_DATA!B:B,A7,RAW_DATA!L:L) -> 52.384 | J7: =AVERAGEIF(RAW_DATA!B:B,A7,RAW_DATA!M:M) -> 28.886667 | K7: =SUMIF(RAW_DATA!B:B,A7,RAW_DATA!I:I) -> 264360884000 | L7: =AVERAGEIF(RAW_DATA!B:B,A7,RAW_DATA!H:H) -> 77480426200 | M7: =SUMIF(RAW_DATA!B:B,A7,RAW_DATA!E:E) -> 1844358566000 | N7: =AVERAGEIF(RAW_DATA!B:B,A7,RAW_DATA!E:E) -> 368871713200 | O7: =COUNTIFS(RAW_DATA!B:B,A7,RAW_DATA!H:H,">0") -> 5 | P7: =COUNTIFS(RAW_DATA!B:B,A7,RAW_DATA!M:M,">0") -> 2 | Q7: =MAXIFS(RAW_DATA!L:L,RAW_DATA!B:B,A7) -> 120.64 | R7: =MAXIFS(RAW_DATA!M:M,RAW_DATA!B:B,A7) -> 44.66 | S7: =MAXIFS(RATIOS!C:C,RATIOS!A:A,A7) -> 0.64872803 | T7: =MAXIFS(RATIOS!H:H,RATIOS!A:A,A7) -> 1.5215059 | U7: =MAXIFS(RATIOS!G:G,RATIOS!A:A,A7) -> 1.7901184 | V7: 41.905802 | W7: 100 | X7: 70.253668 | Y7: 67.838421

Sheet Sheet10
A1: COMPANY | B1: ROE SCORE | C1: ROA SCORE | D1: AVG Debt/Equity | E1: AVG Equity Ratio(%) | F1: AVG Asset Growth(%) | G1: AVG Profit Growth(%) | H1: EPS SCORE | I1: DPS SCORE | J1: Profitability Score | K1: Growth Score | L1: Financial Health Score | M1: OVERALL INVESTMENT SCORE | N1: ROE SCORE | O1: ROA SCORE | P1: EPS SCORE | Q1: DPS SCORE | R1: ASSET GROWTH SCORE | S1: PROFIT GROWTH SCORE | U1: EQUTY SCORE | V1: DEBT SCORE
A2: GTCO | B2: ='COMPANY SUMMARY'!C2 -> 0.27023379 | C2: ='COMPANY SUMMARY'!D2 -> 0.045393969 | D2: ='COMPANY SUMMARY'!E2 -> 5.0620582 | E2: ='COMPANY SUMMARY'!F2 -> 0.16656803 | F2: ='COMPANY SUMMARY'!G2 -> 0.30314605 | G2: ='COMPANY SUMMARY'!H2 -> 0.55242405 | H2: ='COMPANY SUMMARY'!I2 -> 16.523333 | I2: ='COMPANY SUMMARY'!J2 -> 4.005 | J2: =AVERAGE(N2:Q2) -> 9.651591 | K2: =AVERAGE(R2:S2) -> 48.669743 | L2: =0.3*T2+0.4*U2+0.3*V2 -> 22.176352 | M2: =(J2*0.4)+(K2*0.3)+(L2*0.3) -> 25.114465 | N2: =(B2-MIN($B$2:$B$7))/(MAX($B$2:$B$7)-MIN($B$2:$B$7))*100 -> 13.907195 | O2: =(C2-MIN($C$2:$C$7))/(MAX($C$2:$C$7)-MIN($C$2:$C$7))*100 -> 21.43058 | P2: =(H2-MIN($H$2:$H$7))/(MAX($H$2:$H$7)-MIN($H$2:$H$7))*100 -> 3.2685884 | Q2: =(I2-MIN($I$2:$I$7))/(MAX($I$2:$I$7)-MIN($I$2:$I$7))*100 -> 0 | R2: =(F2-MIN($F$2:$F$7))/(MAX($F$2:$F$7)-MIN($F$2:$F$7))*100 -> 14.826828 | S2: =(G2-MIN($G$2:$G$7))/(MAX($G$2:$G$7)-MIN($G$2:$G$7))*100 -> 82.512658 | T2: =(C2-MIN($C$2:$C$7))/(MAX($C$2:$C$7)-MIN($C$2:$C$7))*100 -> 21.43058 | U2: =(E2-MIN($E$2:$E$7))/(MAX($E$2:$E$7)-MIN($E$2:$E$7))*100 -> 31.365159 | V2: =(MAX($D$2:$D$7)-D2)/(MAX($D$2:$D$7)-MIN($D$2:$D$7))*100 -> 10.670379
A3: Zenith Bank | B3: ='COMPANY SUMMARY'!C3 -> 0.21980407 | C3: ='COMPANY SUMMARY'!D3 -> 0.0286808 | D3: ='COMPANY SUMMARY'!E3 -> 6.7453993 | E3: ='COMPANY SUMMARY'!F3 -> 0.13075703 | F3: ='COMPANY SUMMARY'!G3 -> 0.31862129 | G3: ='COMPANY SUMMARY'!H3 -> 0.50653745 | H3: ='COMPANY SUMMARY'!I3 -> 17 | I3: ='COMPANY SUMMARY'!J3 -> 4.1083333 | J3: =AVERAGE(N3:Q3) -> 5.6515914 | K3: =AVERAGE(R3:S3) -> 48.415743 | L3: =0.3*T3+0.4*U3+0.3*V3 -> 11.203408 | M3: =(J3*0.4)+(K3*0.3)+(L3*0.3) -> 20.146382 | N3: =(B3-MIN($B$2:$B$7))/(MAX($B$2:$B$7)-MIN($B$2:$B$7))*100 -> 10.74637 | O3: =(C3-MIN($C$2:$C$7))/(MAX($C$2:$C$7)-MIN($C$2:$C$7))*100 -> 8.2110555 | P3: =(H3-MIN($H$2:$H$7))/(MAX($H$2:$H$7)-MIN($H$2:$H$7))*100 -> 3.5849391 | Q3: =(I3-MIN($I$2:$I$7))/(MAX($I$2:$I$7)-MIN($I$2:$I$7))*100 -> 0.064001321 | R3: =(F3-MIN($F$2:$F$7))/(MAX($F$2:$F$7)-MIN($F$2:$F$7))*100 -> 17.831956 | S3: =(G3-MIN($G$2:$G$7))/(MAX($G$2:$G$7)-MIN($G$2:$G$7))*100 -> 78.999529 | T3: =(C3-MIN($C$2:$C$7))/(MAX($C$2:$C$7)-MIN($C$2:$C$7))*100 -> 8.2110555 | U3: =(E3-MIN($E$2:$E$7))/(MAX($E$2:$E$7)-MIN($E$2:$E$7))*100 -> 21.850227 | V3: =(MAX($D$2:$D$7)-D3)/(MAX($D$2:$D$7)-MIN($D$2:$D$7))*100 -> 0
A4: MTN | B4: ='COMPANY SUMMARY'!C4 -> 1.6438102 | C4: ='COMPANY SUMMARY'!D4 -> 0.073597475 | D4: ='COMPANY SUMMARY'!E4 -> -9.0304322 | E4: ='COMPANY SUMMARY'!F4 -> 0.048520137 | F4: ='COMPANY SUMMARY'!G4 -> 0.22679361 | G4: ='COMPANY SUMMARY'!H4 -> -0.52531183 | H4: ='COMPANY SUMMARY'!I4 -> 11.598333 | I4: ='COMPANY SUMMARY'!J4 -> 10.616667 | J4: =AVERAGE(N4:Q4) -> 36.958402 | K4: =AVERAGE(R4:S4) -> 0 | L4: =0.3*T4+0.4*U4+0.3*V4 -> 43.121567 | M4: =(J4*0.4)+(K4*0.3)+(L4*0.3) -> 27.719831 | N4: =(B4-MIN($B$2:$B$7))/(MAX($B$2:$B$7)-MIN($B$2:$B$7))*100 -> 100 | O4: =(C4-MIN($C$2:$C$7))/(MAX($C$2:$C$7)-MIN($C$2:$C$7))*100 -> 43.738555 | P4: =(H4-MIN($H$2:$H$7))/(MAX($H$2:$H$7)-MIN($H$2:$H$7))*100 -> 0 | Q4: =(I4-MIN($I$2:$I$7))/(MAX($I$2:$I$7)-MIN($I$2:$I$7))*100 -> 4.0950523 | R4: =(F4-MIN($F$2:$F$7))/(MAX($F$2:$F$7)-MIN($F$2:$F$7))*100 -> 0 | S4: =(G4-MIN($G$2:$G$7))/(MAX($G$2:$G$7)-MIN($G$2:$G$7))*100 -> 0 | T4: =(C4-MIN($C$2:$C$7))/(MAX($C$2:$C$7)-MIN($C$2:$C$7))*100 -> 43.738555 | U4: =(E4-MIN($E$2:$E$7))/(MAX($E$2:$E$7)-MIN($E$2:$E$7))*100 -> 0 | V4: =(MAX($D$2:$D$7)-D4)/(MAX($D$2:$D$7)-MIN($D$2:$D$7))*100 -> 100
A5: DANGCEM | B5: ='COMPANY SUMMARY'!C5 -> 0.31956023 | C5: ='COMPANY SUMMARY'!D5 -> 0.1328823 | D5: ='COMPANY SUMMARY'!E5 -> 1.4428893 | E5: ='COMPANY SUMMARY'!F5 -> 0.4126488 | F5: ='COMPANY SUMMARY'!G5 -> 0.27023048 | G5: ='COMPANY SUMMARY'!H5 -> 0.33643368 | H5: ='COMPANY SUMMARY'!I5 -> 29.286667 | I5: ='COMPANY SUMMARY'!J5 -> 26.833333 | J5: =AVERAGE(N5:Q5) -> 33.377005 | K5: =AVERAGE(R5:S5) -> 37.205586 | L5: =0.3*T5+0.4*U5+0.3*V5 -> 75.972096 | M5: =(J5*0.4)+(K5*0.3)+(L5*0.3) -> 47.304107 | N5: =(B5-MIN($B$2:$B$7))/(MAX($B$2:$B$7)-MIN($B$2:$B$7))*100 -> 16.99887 | O5: =(C5-MIN($C$2:$C$7))/(MAX($C$2:$C$7)-MIN($C$2:$C$7))*100 -> 90.630756 | P5: =(H5-MIN($H$2:$H$7))/(MAX($H$2:$H$7)-MIN($H$2:$H$7))*100 -> 11.739265 | Q5: =(I5-MIN($I$2:$I$7))/(MAX($I$2:$I$7)-MIN($I$2:$I$7))*100 -> 14.139131 | R5: =(F5-MIN($F$2:$F$7))/(MAX($F$2:$F$7)-MIN($F$2:$F$7))*100 -> 8.4349767 | S5: =(G5-MIN($G$2:$G$7))/(MAX($G$2:$G$7)-MIN($G$2:$G$7))*100 -> 65.976195 | T5: =(C5-MIN($C$2:$C$7))/(MAX($C$2:$C$7)-MIN($C$2:$C$7))*100 -> 90.630756 | U5: =(E5-MIN($E$2:$E$7))/(MAX($E$2:$E$7)-MIN($E$2:$E$7))*100 -> 96.748469 | V5: =(MAX($D$2:$D$7)-D5)/(MAX($D$2:$D$7)-MIN($D$2:$D$7))*100 -> 33.611604
A6: Seplat | B6: ='COMPANY SUMMARY'!C6 -> 0.048350022 | C6: ='COMPANY SUMMARY'!D6 -> 0.018299734 | D6: ='COMPANY SUMMARY'!E6 -> 1.5260818 | E6: ='COMPANY SUMMARY'!F6 -> 0.42488646 | F6: ='COMPANY SUMMARY'!G6 -> 0.69352583 | G6: ='COMPANY SUMMARY'!H6 -> -0.0065770241 | H6: ='COMPANY SUMMARY'!I6 -> 162.275 | I6: ='COMPANY SUMMARY'!J6 -> 165.46 | J6: =AVERAGE(N6:Q6) -> 50 | K6: =AVERAGE(R6:S6) -> 65.174668 | L6: =0.3*T6+0.4*U6+0.3*V6 -> 49.925279 | M6: =(J6*0.4)+(K6*0.3)+(L6*0.3) -> 54.529984 | N6: =(B6-MIN($B$2:$B$7))/(MAX($B$2:$B$7)-MIN($B$2:$B$7))*100 -> 0 | O6: =(C6-MIN($C$2:$C$7))/(MAX($C$2:$C$7)-MIN($C$2:$C$7))*100 -> 0 | P6: =(H6-MIN($H$2:$H$7))/(MAX($H$2:$H$7)-MIN($H$2:$H$7))*100 -> 100 | Q6: =(I6-MIN($I$2:$I$7))/(MAX($I$2:$I$7)-MIN($I$2:$I$7))*100 -> 100 | R6: =(F6-MIN($F$2:$F$7))/(MAX($F$2:$F$7)-MIN($F$2:$F$7))*100 -> 90.634422 | S6: =(G6-MIN($G$2:$G$7))/(MAX($G$2:$G$7)-MIN($G$2:$G$7))*100 -> 39.714914 | T6: =(C6-MIN($C$2:$C$7))/(MAX($C$2:$C$7)-MIN($C$2:$C$7))*100 -> 0 | U6: =(E6-MIN($E$2:$E$7))/(MAX($E$2:$E$7)-MIN($E$2:$E$7))*100 -> 100 | V6: =(MAX($D$2:$D$7)-D6)/(MAX($D$2:$D$7)-MIN($D$2:$D$7))*100 -> 33.084262
A7: Presco | B7: ='COMPANY SUMMARY'!C7 -> 0.4495121 | C7: ='COMPANY SUMMARY'!D7 -> 0.14472764 | D7: ='COMPANY SUMMARY'!E7 -> 2.1832401 | E7: ='COMPANY SUMMARY'!F7 -> 0.34564319 | F7: ='COMPANY SUMMARY'!G7 -> 0.74175494 | G7: ='COMPANY SUMMARY'!H7 -> 0.78083429 | H7: ='COMPANY SUMMARY'!I7 -> 52.384 | I7: ='COMPANY SUMMARY'!J7 -> 28.886667 | J7: =AVERAGE(N7:Q7) -> 41.905802 | K7: =AVERAGE(R7:S7) -> 100 | L7: =0.3*T7+0.4*U7+0.3*V7 -> 70.253668 | M7: =(J7*0.4)+(K7*0.3)+(L7*0.3) -> 67.838421 | N7: =(B7-MIN($B$2:$B$7))/(MAX($B$2:$B$7)-MIN($B$2:$B$7))*100 -> 25.143972 | O7: =(C7-MIN($C$2:$C$7))/(MAX($C$2:$C$7)-MIN($C$2:$C$7))*100 -> 100 | P7: =(H7-MIN($H$2:$H$7))/(MAX($H$2:$H$7)-MIN($H$2:$H$7))*100 -> 27.068336 | Q7: =(I7-MIN($I$2:$I$7))/(MAX($I$2:$I$7)-MIN($I$2:$I$7))*100 -> 15.410899 | R7: =(F7-MIN($F$2:$F$7))/(MAX($F$2:$F$7)-MIN($F$2:$F$7))*100 -> 100 | S7: =(G7-MIN($G$2:$G$7))/(MAX($G$2:$G$7)-MIN($G$2:$G$7))*100 -> 100 | T7: =(C7-MIN($C$2:$C$7))/(MAX($C$2:$C$7)-MIN($C$2:$C$7))*100 -> 100 | U7: =(E7-MIN($E$2:$E$7))/(MAX($E$2:$E$7)-MIN($E$2:$E$7))*100 -> 78.945174 | V7: =(MAX($D$2:$D$7)-D7)/(MAX($D$2:$D$7)-MIN($D$2:$D$7))*100 -> 28.918661
B8: ='COMPANY SUMMARY'!C8

Sheet RATIOS
A1: COMPANY | B1: YEAR | C1: ROE(%) | D1: ROA(%) | E1: BEBT-TO-EQUITY | F1: EQUITY RATIO(%) | G1: ASSET GROWTH(%) | H1: PROFIT GROWTH(%)
A2: GTCO | B2: 2020 | C2: =(RAW_DATA!I2/RAW_DATA!G2) -> 0.24734898 | D2: =(RAW_DATA!I2/RAW_DATA!E2) -> 0.040738941 | E2: =RAW_DATA!F2/RAW_DATA!G2 -> 5.0715613 | F2: =(RAW_DATA!G2/RAW_DATA!E2) -> 0.16470228 | G2: N/A | H2: N/A
A3: GTCO | B3: 2021 | C3: =(RAW_DATA!I3/RAW_DATA!G3) -> 0.1979553 | D3: =(RAW_DATA!I3/RAW_DATA!E3) -> 0.032163054 | E3: =RAW_DATA!F3/RAW_DATA!G3 -> 5.1547421 | F3: =(RAW_DATA!G3/RAW_DATA!E3) -> 0.16247634 | G3: =((RAW_DATA!E3-RAW_DATA!E2)/RAW_DATA!E2) -> 0.099376372 | H3: =((RAW_DATA!I3-RAW_DATA!I2)/RAW_DATA!I2) -> -0.13205153
A4: GTCO | B4: 2022 | C4: =(RAW_DATA!I4/RAW_DATA!G4) -> 0.18168242 | D4: =(RAW_DATA!I4/RAW_DATA!E4) -> 0.026242857 | E4: =RAW_DATA!F4/RAW_DATA!G4 -> 5.9231187 | F4: =(RAW_DATA!G4/RAW_DATA!E4) -> 0.14444357 | G4: =((RAW_DATA!E4-RAW_DATA!E3)/RAW_DATA!E3) -> 0.18587471 | H4: =((RAW_DATA!I4-RAW_DATA!I3)/RAW_DATA!I3) -> -0.032407153
A5: GTCO | B5: 2023 | C5: =(RAW_DATA!I5/RAW_DATA!G5) -> 0.36534048 | D5: =(RAW_DATA!I5/RAW_DATA!E5) -> 0.055684707 | E5: =RAW_DATA!F5/RAW_DATA!G5 -> 5.5608764 | F5: =(RAW_DATA!G5/RAW_DATA!E5) -> 0.15241866 | G5: =((RAW_DATA!E5-RAW_DATA!E4)/RAW_DATA!E4) -> 0.50334603 | H5: =((RAW_DATA!I5-RAW_DATA!I4)/RAW_DATA!I4) -> 2.1899492
A6: GTCO | B6: 2024 | C6: =(RAW_DATA!I6/RAW_DATA!G6) -> 0.3752936 | D6: =(RAW_DATA!I6/RAW_DATA!E6) -> 0.068790417 | E6: =RAW_DATA!F6/RAW_DATA!G6 -> 4.4556087 | F6: =(RAW_DATA!G6/RAW_DATA!E6) -> 0.1832976 | G6: =((RAW_DATA!E6-RAW_DATA!E5)/RAW_DATA!E5) -> 0.52670705 | H6: =((RAW_DATA!I6-RAW_DATA!I5)/RAW_DATA!I5) -> 0.88602619
A7: GTCO | B7: 2025 | C7: =(RAW_DATA!I7/RAW_DATA!G7) -> 0.25378196 | D7: =(RAW_DATA!I7/RAW_DATA!E7) -> 0.048743836 | E7: =RAW_DATA!F7/RAW_DATA!G7 -> 4.2064421 | F7: =(RAW_DATA!G7/RAW_DATA!E7) -> 0.19206974 | G7: =((RAW_DATA!E7-RAW_DATA!E6)/RAW_DATA!E6) -> 0.20042607 | H7: =((RAW_DATA!I7-RAW_DATA!I6)/RAW_DATA!I6) -> -0.14939648
A8: Zenith Bank | B8: 2020 | C8: =(RAW_DATA!I8/RAW_DATA!G8) -> 0.20632713 | D8: =(RAW_DATA!I8/RAW_DATA!E8) -> 0.027185188 | E8: =RAW_DATA!F8/RAW_DATA!G8 -> 6.5896894 | F8: =(RAW_DATA!G8/RAW_DATA!E8) -> 0.1317577 | G8: N/A | H8: N/A
A9: Zenith Bank | B9: 2021 | C9: =(RAW_DATA!I9/RAW_DATA!G9) -> 0.1911114 | D9: =(RAW_DATA!I9/RAW_DATA!E9) -> 0.025885062 | E9: =RAW_DATA!F9/RAW_DATA!G9 -> 6.3830769 | F9: =(RAW_DATA!G9/RAW_DATA!E9) -> 0.13544488 | G9: =((RAW_DATA!E9-RAW_DATA!E8)/RAW_DATA!E8) -> 0.1139652 | H9: =((RAW_DATA!I9-RAW_DATA!I8)/RAW_DATA!I8) -> 0.060690044
A10: Zenith Bank | B10: 2022 | C10: =(RAW_DATA!I10/RAW_DATA!G10) -> 0.16237907 | D10: =(RAW_DATA!I10/RAW_DATA!E10) -> 0.01822544 | E10: =RAW_DATA!F10/RAW_DATA!G10 -> 7.9094732 | F10: =(RAW_DATA!G10/RAW_DATA!E10) -> 0.11224008 | G10: =((RAW_DATA!E10-RAW_DATA!E9)/RAW_DATA!E9) -> 0.30036337 | H10: =((RAW_DATA!I10-RAW_DATA!I9)/RAW_DATA!I9) -> -0.08442578
A11: Zenith Bank | B11: 2023 | C11: =(RAW_DATA!I11/RAW_DATA!G11) -> 0.29134666 | D11: =(RAW_DATA!I11/RAW_DATA!E11) -> 0.033233203 | E11: =RAW_DATA!F11/RAW_DATA!G11 -> 7.7667342 | F11: =(RAW_DATA!G11/RAW_DATA!E11) -> 0.11406756 | G11: =((RAW_DATA!E11-RAW_DATA!E10)/RAW_DATA!E10) -> 0.65790901 | H11: =((RAW_DATA!I11-RAW_DATA!I10)/RAW_DATA!I10) -> 2.0231163
A12: Zenith Bank | B12: 2024 | C12: =(RAW_DATA!I12/RAW_DATA!G12) -> 0.25634773 | D12: =(RAW_DATA!I12/RAW_DATA!E12) -> 0.034478649 | E12: =RAW_DATA!F12/RAW_DATA!G12 -> 6.4349703 | F12: =(RAW_DATA!G12/RAW_DATA!E12) -> 0.13449953 | G12: =((RAW_DATA!E12-RAW_DATA!E11)/RAW_DATA!E11) -> 0.47078043 | H12: =((RAW_DATA!I12-RAW_DATA!I11)/RAW_DATA!I11) -> 0.52589935
A13: Zenith Bank | B13: 2025 | C13: =(RAW_DATA!I13/RAW_DATA!G13) -> 0.21131244 | D13: =(RAW_DATA!I13/RAW_DATA!E13) -> 0.033077256 | E13: =RAW_DATA!F13/RAW_DATA!G13 -> 5.3884515 | F13: =(RAW_DATA!G13/RAW_DATA!E13) -> 0.15653246 | G13: =((RAW_DATA!E13-RAW_DATA!E12)/RAW_DATA!E12) -> 0.05008845 | H13: =((RAW_DATA!I13-RAW_DATA!I12)/RAW_DATA!I12) -> 0.0074073357
A14: MTN | B14: 2020 | C14: =(RAW_DATA!I14/RAW_DATA!G14) -> 1.150393 | D14: =(RAW_DATA!I14/RAW_DATA!E14) -> 0.1045121 | E14: =RAW_DATA!F14/RAW_DATA!G14 -> 10.007271 | F14: =(RAW_DATA!G14/RAW_DATA!E14) -> 0.090849042 | G14: N/A | H14: N/A
A15: MTN | B15: 2021 | C15: =(RAW_DATA!I15/RAW_DATA!G15) -> 1.127077 | D15: =(RAW_DATA!I15/RAW_DATA!E15) -> 0.13217381 | E15: =RAW_DATA!F15/RAW_DATA!G15 -> 7.527234 | F15: =(RAW_DATA!G15/RAW_DATA!E15) -> 0.11727132 | G15: =((RAW_DATA!E15-RAW_DATA!E14)/RAW_DATA!E14) -> 0.15075402 | H15: =((RAW_DATA!I15-RAW_DATA!I14)/RAW_DATA!I14) -> 0.45532956
A16: MTN | B16: 2022 | C16: =(RAW_DATA!I16/RAW_DATA!G16) -> 1.3282713 | D16: =(RAW_DATA!I16/RAW_DATA!E16) -> 0.13732821 | E16: =RAW_DATA!F16/RAW_DATA!G16 -> 8.6722391 | F16: =(RAW_DATA!G16/RAW_DATA!E16) -> 0.10338868 | G16: =((RAW_DATA!E16-RAW_DATA!E15)/RAW_DATA!E15) -> 0.12383589 | H16: =((RAW_DATA!I16-RAW_DATA!I15)/RAW_DATA!I15) -> 0.16766224
A17: MTN | B17: 2023 | C17: =(RAW_DATA!I17/RAW_DATA!G17) -> 3.3547155 | D17: =(RAW_DATA!I17/RAW_DATA!E17) -> -0.042968778 | E17: =RAW_DATA!F17/RAW_DATA!G17 -> -79.073328 | F17: =(RAW_DATA!G17/RAW_DATA!E17) -> -0.012808472 | G17: =((RAW_DATA!E17-RAW_DATA!E16)/RAW_DATA!E16) -> 0.25575566 | H17: =((RAW_DATA!I17-RAW_DATA!I16)/RAW_DATA!I16) -> -1.3929148
A18: MTN | B18: 2024 | C18: =(RAW_DATA!I18/RAW_DATA!G18) -> 0.87429886 | D18: =(RAW_DATA!I18/RAW_DATA!E18) -> -0.095410021 | E18: =RAW_DATA!F18/RAW_DATA!G18 -> -10.163596 | F18: =(RAW_DATA!G18/RAW_DATA!E18) -> -0.10912747 | G18: =((RAW_DATA!E18-RAW_DATA!E17)/RAW_DATA!E17) -> 0.31615513 | H18: =((RAW_DATA!I18-RAW_DATA!I17)/RAW_DATA!I17) -> 1.9224566
A19: MTN | B19: 2025 | C19: =(RAW_DATA!I19/RAW_DATA!G19) -> 2.0281058 | D19: =(RAW_DATA!I19/RAW_DATA!E19) -> 0.20594953 | E19: =RAW_DATA!F19/RAW_DATA!G19 -> 8.8475867 | F19: =(RAW_DATA!G19/RAW_DATA!E19) -> 0.10154772 | G19: =((RAW_DATA!E19-RAW_DATA!E18)/RAW_DATA!E18) -> 0.28746738 | H19: =((RAW_DATA!I19-RAW_DATA!I18)/RAW_DATA!I18) -> -3.7790927
A20: Presco | B20: 2020 | C20: N/A | D20: N/A | E20: N/A | F20: N/A | G20: N/A | H20: N/A
A21: Presco | B21: 2021 | C21: =(RAW_DATA!I21/RAW_DATA!G21) -> 0.64872803 | D21: =(RAW_DATA!I21/RAW_DATA!E21) -> 0.13740459 | E21: =RAW_DATA!F21/RAW_DATA!G21 -> 3.721298 | F21: =(RAW_DATA!G21/RAW_DATA!E21) -> 0.21180616 | G21: N/A | H21: N/A
A22: Presco | B22: 2022 | C22: =(RAW_DATA!I22/RAW_DATA!G22) -> 0.38150493 | D22: =(RAW_DATA!I22/RAW_DATA!E22) -> 0.098454924 | E22: =RAW_DATA!F22/RAW_DATA!G22 -> 2.8749198 | F22: =(RAW_DATA!G22/RAW_DATA!E22) -> 0.25806986 | G22: =((RAW_DATA!E22-RAW_DATA!E21)/RAW_DATA!E21) -> -0.05858104 | H22: =((RAW_DATA!I22-RAW_DATA!I21)/RAW_DATA!I21) -> -0.32544225
A23: Presco | B23: 2023 | C23: =(RAW_DATA!I23/RAW_DATA!G23) -> 0.57487017 | D23: =(RAW_DATA!I23/RAW_DATA!E23) -> 0.19298621 | E23: =RAW_DATA!F23/RAW_DATA!G23 -> 1.9788147 | F23: =(RAW_DATA!G23/RAW_DATA!E23) -> 0.33570399 | G23: =((RAW_DATA!E23-RAW_DATA!E22)/RAW_DATA!E22) -> 0.28638555 | H23: =((RAW_DATA!I23-RAW_DATA!I22)/RAW_DATA!I22) -> 1.5215059
A24: Presco | B24: 2024 | C24: =(RAW_DATA!I24/RAW_DATA!G24) -> 0.36836533 | D24: =(RAW_DATA!I24/RAW_DATA!E24) -> 0.16374176 | E24: =RAW_DATA!F24/RAW_DATA!G24 -> 1.2496725 | F24: =(RAW_DATA!G24/RAW_DATA!E24) -> 0.44450915 | G24: =((RAW_DATA!E24-RAW_DATA!E23)/RAW_DATA!E23) -> 1.7901184 | H24: =((RAW_DATA!I24-RAW_DATA!I23)/RAW_DATA!I23) -> 1.3673137
A25: Presco | B25: 2025 | C25: =(RAW_DATA!I25/RAW_DATA!G25) -> 0.27409201 | D25: =(RAW_DATA!I25/RAW_DATA!E25) -> 0.13105073 | E25: =RAW_DATA!F25/RAW_DATA!G25 -> 1.0914955 | F25: =(RAW_DATA!G25/RAW_DATA!E25) -> 0.47812678 | G25: =((RAW_DATA!E25-RAW_DATA!E24)/RAW_DATA!E24) -> 0.94909682 | H25: =((RAW_DATA!I25-RAW_DATA!I24)/RAW_DATA!I24) -> 0.5599598
A26: DANGCEM | B26: 2020 | C26: =(RAW_DATA!I26/RAW_DATA!G26) -> 0.30985106 | D26: =(RAW_DATA!I26/RAW_DATA!E26) -> 0.1365017 | E26: =RAW_DATA!F26/RAW_DATA!G26 -> 1.2699429 | F26: =(RAW_DATA!G26/RAW_DATA!E26) -> 0.44053972 | G26: N/A | H26: N/A
A27: DANGCEM | B27: 2021 | C27: =(RAW_DATA!I27/RAW_DATA!G27) -> 0.37048946 | D27: =(RAW_DATA!I27/RAW_DATA!E27) -> 0.15235623 | E27: =RAW_DATA!F27/RAW_DATA!G27 -> 1.4317316 | F27: =(RAW_DATA!G27/RAW_DATA!E27) -> 0.41122959 | G27: =((RAW_DATA!E27-RAW_DATA!E26)/RAW_DATA!E26) -> 0.18273273 | H27: =((RAW_DATA!I27-RAW_DATA!I26)/RAW_DATA!I26) -> 0.32010592
A28: DANGCEM | B28: 2022 | C28: =(RAW_DATA!I28/RAW_DATA!G28) -> 0.35433715 | D28: =(RAW_DATA!I28/RAW_DATA!E28) -> 0.14616262 | E28: =RAW_DATA!F28/RAW_DATA!G28 -> 1.4242664 | F28: =(RAW_DATA!G28/RAW_DATA!E28) -> 0.41249591 | G28: =((RAW_DATA!E28-RAW_DATA!E27)/RAW_DATA!E27) -> 0.093492568 | H28: =((RAW_DATA!I28-RAW_DATA!I27)/RAW_DATA!I27) -> 0.049039757
A29: DANGCEM | B29: 2023 | C29: =(RAW_DATA!I29/RAW_DATA!G29) -> 0.26397754 | D29: =(RAW_DATA!I29/RAW_DATA!E29) -> 0.11566763 | E29: =RAW_DATA!F29/RAW_DATA!G29 -> 1.2822075 | F29: =(RAW_DATA!G29/RAW_DATA!E29) -> 0.43817225 | G29: =((RAW_DATA!E29-RAW_DATA!E28)/RAW_DATA!E28) -> 0.50582741 | H29: =((RAW_DATA!I29-RAW_DATA!I28)/RAW_DATA!I28) -> 0.19165548
A30: DANGCEM | B30: 2024 | C30: =(RAW_DATA!I30/RAW_DATA!G30) -> 0.23135187 | D30: =(RAW_DATA!I30/RAW_DATA!E30) -> 0.078592581 | E30: =RAW_DATA!F30/RAW_DATA!G30 -> 1.9436859 | F30: =(RAW_DATA!G30/RAW_DATA!E30) -> 0.33971016 | G30: =((RAW_DATA!E30-RAW_DATA!E29)/RAW_DATA!E29) -> 0.6257134 | H30: =((RAW_DATA!I30-RAW_DATA!I29)/RAW_DATA!I29) -> 0.10462199
A31: DANGCEM | B31: 2025 | C31: =(RAW_DATA!I31/RAW_DATA!G31) -> 0.38735432 | D31: =(RAW_DATA!I31/RAW_DATA!E31) -> 0.16801306 | E31: =RAW_DATA!F31/RAW_DATA!G31 -> 1.3055013 | F31: =(RAW_DATA!G31/RAW_DATA!E31) -> 0.43374514 | G31: =((RAW_DATA!E31-RAW_DATA!E30)/RAW_DATA!E30) -> -0.056613701 | H31: =((RAW_DATA!I31-RAW_DATA!I30)/RAW_DATA!I30) -> 1.0167453
A32: Seplat | B32: 2020 | C32: =(RAW_DATA!I32/RAW_DATA!G32) -> -0.048569038 | D32: =(RAW_DATA!I32/RAW_DATA!E32) -> -0.023429305 | E32: =RAW_DATA!F32/RAW_DATA!G32 -> 1.0730038 | F32: =(RAW_DATA!G32/RAW_DATA!E32) -> 0.48239178 | G32: N/A | H32: N/A
A33: Seplat | B33: 2021 | C33: =(RAW_DATA!I33/RAW_DATA!G33) -> 0.066723631 | D33: =(RAW_DATA!I33/RAW_DATA!E33) -> 0.029267194 | E33: =RAW_DATA!F33/RAW_DATA!G33 -> 1.2798096 | F33: =(RAW_DATA!G33/RAW_DATA!E33) -> 0.43863312 | G33: =((RAW_DATA!E33-RAW_DATA!E32)/RAW_DATA!E32) -> 0.22329168 | H33: =((RAW_DATA!I33-RAW_DATA!I32)/RAW_DATA!I32) -> -2.5280998
A34: Seplat | B34: 2022 | C34: =(RAW_DATA!I34/RAW_DATA!G34) -> 0.056466309 | D34: =(RAW_DATA!I34/RAW_DATA!E34) -> 0.029821206 | E34: =RAW_DATA!F34/RAW_DATA!G34 -> 0.89349518 | F34: =(RAW_DATA!G34/RAW_DATA!E34) -> 0.52812387 | G34: =((RAW_DATA!E34-RAW_DATA!E33)/RAW_DATA!E33) -> -0.070815997 | H34: =((RAW_DATA!I34-RAW_DATA!I33)/RAW_DATA!I33) -> -0.053227078
A35: Seplat | B35: 2023 | C35: =(RAW_DATA!I35/RAW_DATA!G35) -> 0.050432987 | D35: =(RAW_DATA!I35/RAW_DATA!E35) -> 0.02663541 | E35: =RAW_DATA!F35/RAW_DATA!G35 -> 0.89345636 | F35: =(RAW_DATA!G35/RAW_DATA!E35) -> 0.5281347 | G35: =((RAW_DATA!E35-RAW_DATA!E34)/RAW_DATA!E34) -> 1.0493255 | H35: =((RAW_DATA!I35-RAW_DATA!I34)/RAW_DATA!I34) -> 0.83039633
A36: Seplat | B36: 2024 | C36: =(RAW_DATA!I36/RAW_DATA!G36) -> 0.073650696 | D36: =(RAW_DATA!I36/RAW_DATA!E36) -> 0.019829542 | E36: =RAW_DATA!F36/RAW_DATA!G36 -> 2.7141906 | F36: =(RAW_DATA!G36/RAW_DATA!E36) -> 0.26923767 | G36: =((RAW_DATA!E36-RAW_DATA!E35)/RAW_DATA!E35) -> 2.4330938 | H36: =((RAW_DATA!I36-RAW_DATA!I35)/RAW_DATA!I35) -> 1.5558711
A37: Seplat | B37: 2025 | C37: =(RAW_DATA!I37/RAW_DATA!G37) -> 0.091395547 | D37: =(RAW_DATA!I37/RAW_DATA!E37) -> 0.027674356 | E37: =RAW_DATA!F37/RAW_DATA!G37 -> 2.3025356 | F37: =(RAW_DATA!G37/RAW_DATA!E37) -> 0.30279764 | G37: =((RAW_DATA!E37-RAW_DATA!E36)/RAW_DATA!E36) -> -0.16726581 | H37: =((RAW_DATA!I37-RAW_DATA!I36)/RAW_DATA!I36) -> 0.16217425

Sheet INVESTMENT_NOTES
A1: COMPANY | B1: YEAR | C1: SUMMARY | D1: RECOMMENDATIONS
A2: GTCO | B2: 2021 | C2: Profitability weakened compared to 2020 as ROE and ROA declined. However, the bank remained highly profitable and maintained a strong capital position. Overall financial health remained solid. | D2: Hold/Buy on weakness
